<?xml version="1.0"?>
<robot name="right_arm_robot">
  <!-- Root link -->
  <link name="world"/>

  <!-- Right Arm Base Link -->
  <link name="r_base_link1">
    <visual>
      <geometry>
        <box size="0.1 0.1 0.1"/>
      </geometry>
    </visual>
  </link>

  <joint name="r_world_to_base" type="fixed">
    <parent link="world"/>
    <child link="r_base_link1"/>
    <origin xyz="0 0 0" rpy="0 0 0"/>
  </joint>

  <!-- Right Arm Links and Joints (unchanged from original) -->
  <link name="r_link1">
    <visual>
      <geometry>
        <box size="0.1 0.1 0.2405"/>
      </geometry>
    </visual>
  </link>

  <joint name="r_joint1" type="revolute">
    <origin xyz="0 0 0.2405" rpy="-1.5708 0 0"/>
    <parent link="r_base_link1"/>
    <child link="r_link1"/>
    <axis xyz="0 -1 0"/>
    <limit effort="0" velocity="0" lower="-3.1102" upper="3.1102"/>
  </joint>

  <link name="r_link2">
    <visual>
      <geometry>
        <box size="0.1 0.1 0.1"/>
      </geometry>
    </visual>
  </link>

  <joint name="r_joint2" type="revolute">
    <origin xyz="0 0 0" rpy="1.5708 0 0"/>
    <parent link="r_link1"/>
    <child link="r_link2"/>
    <axis xyz="0 1 0"/>
    <limit effort="0" velocity="0" lower="-2.2700" upper="2.2700"/>
  </joint>

  <link name="r_link3">
    <visual>
      <geometry>
        <box size="0.1 0.1 0.256"/>
      </geometry>
    </visual>
  </link>

  <joint name="r_joint3" type="revolute">
    <origin xyz="0 0 0.256" rpy="-1.5708 0 0"/>
    <parent link="r_link2"/>
    <child link="r_link3"/>
    <axis xyz="0 -1 0"/>
    <limit effort="0" velocity="0" lower="-3.1102" upper="3.1102"/>
  </joint>

  <link name="r_link4">
    <visual>
      <geometry>
        <box size="0.1 0.1 0.1"/>
      </geometry>
    </visual>
  </link>

  <joint name="r_joint4" type="revolute">
    <origin xyz="0 0 0" rpy="1.5708 0 0"/>
    <parent link="r_link3"/>
    <child link="r_link4"/>
    <axis xyz="0 1 0"/>
    <limit effort="0" velocity="0" lower="-2.3598" upper="2.3598"/>
  </joint>

  <link name="r_link5">
    <visual>
      <geometry>
        <box size="0.1 0.1 0.210"/>
      </geometry>
    </visual>
  </link>

  <joint name="r_joint5" type="revolute">
    <origin xyz="0 -0.00030007 0.210" rpy="-1.5708 0 0"/>
    <parent link="r_link4"/>
    <child link="r_link5"/>
    <axis xyz="0 -1 0"/>
    <limit effort="0" velocity="0" lower="-3.1102" upper="3.1102"/>
  </joint>

  <link name="r_link6">
    <visual>
      <geometry>
        <box size="0.1 0.1 0.1"/>
      </geometry>
    </visual>
  </link>

  <joint name="r_joint6" type="revolute">
    <origin xyz="0 0 0" rpy="1.5709 0 0"/>
    <parent link="r_link5"/>
    <child link="r_link6"/>
    <axis xyz="0 1 0"/>
    <limit effort="0" velocity="0" lower="-2.2299" upper="2.2299"/>
  </joint>

  <link name="r_link7">
    <visual>
      <geometry>
        <box size="0.1 0.1 0.1666"/>
      </geometry>
    </visual>
  </link>

  <joint name="r_joint7" type="revolute">
    <origin xyz="0 0.00030429 0.1666" rpy="0 0 0"/>
    <parent link="r_link6"/>
    <child link="r_link7"/>
    <axis xyz="0 0 1"/>
    <limit effort="0" velocity="0" lower="-6.2800" upper="6.2800"/>
  </joint>

  <!-- ... (Rest of right arm joints/links unchanged) ... -->
  <!-- Include all remaining right arm links/joints from original file -->
</robot>