<?xml version="1.0"?>
<robot name="left_arm_robot">
  <!-- Root link -->
  <link name="world"/>

  <!-- Left Arm Base Link -->
  <link name="l_base_link1">
    <visual>
      <geometry>
        <box size="0.1 0.1 0.1"/>
      </geometry>
    </visual>
  </link>

  <!-- Connect directly to world (origin adjusted from platform_base_link) --> 
  <joint name="l_world_to_base" type="fixed">
    <parent link="world"/>
    <child link="l_base_link1"/>
    <origin xyz="0 0 0" rpy="0 0 0"/>
  </joint>

  <!-- Left Arm Links and Joints (unchanged from original) -->
  <link name="l_link1">
    <visual>
      <geometry>
        <box size="0.1 0.1 0.2405"/>
      </geometry>
    </visual>
  </link>

  <joint name="l_joint1" type="revolute">
    <origin xyz="0 0 0.2405" rpy="-1.5708 0 0"/>
    <parent link="l_base_link1"/>
    <child link="l_link1"/>
    <axis xyz="0 -1 0"/>
    <limit effort="0" velocity="0" lower="-3.1102" upper="3.1102"/>
  </joint>

   <link name="l_link2">
    <visual>
      <geometry>
        <box size="0.1 0.1 0.1"/>
      </geometry>
    </visual>
  </link>

  <joint name="l_joint2" type="revolute">
    <origin xyz="0 0 0" rpy="1.5708 0 0"/>
    <parent link="l_link1"/>
    <child link="l_link2"/>
    <axis xyz="0 1 0"/>
    <limit effort="0" velocity="0" lower="-2.2700" upper="2.2700"/>
  </joint>

  <link name="l_link3">
    <visual>
      <geometry>
        <box size="0.1 0.1 0.256"/>
      </geometry>
    </visual>
  </link>

  <joint name="l_joint3" type="revolute">
    <origin xyz="0 0 0.256" rpy="-1.5708 0 0"/>
    <parent link="l_link2"/>
    <child link="l_link3"/>
    <axis xyz="0 -1 0"/>
    <limit effort="0" velocity="0" lower="-3.1102" upper="3.1102"/>
  </joint>

  <link name="l_link4">
    <visual>
      <geometry>
        <box size="0.1 0.1 0.1"/>
      </geometry>
    </visual>
  </link>

  <joint name="l_joint4" type="revolute">
    <origin xyz="0 0 0" rpy="1.5708 0 0"/>
    <parent link="l_link3"/>
    <child link="l_link4"/>
    <axis xyz="0 1 0"/>
    <limit effort="0" velocity="0" lower="-2.3598" upper="2.3598"/>
  </joint>

  <link name="l_link5">
    <visual>
      <geometry>
        <box size="0.1 0.1 0.210"/>
      </geometry>
    </visual>
  </link>

  <joint name="l_joint5" type="revolute">
    <origin xyz="0 -0.00030001 0.210" rpy="-1.5708 0 0"/>
    <parent link="l_link4"/>
    <child link="l_link5"/>
    <axis xyz="0 -1 0"/>
    <limit effort="0" velocity="0" lower="-3.1102" upper="3.1102"/>
  </joint>

  <link name="l_link6">
    <visual>
      <geometry>
        <box size="0.1 0.1 0.1"/>
      </geometry>
    </visual>
  </link>

  <joint name="l_joint6" type="revolute">
    <origin xyz="0 0 0" rpy="1.5708 0 0"/>
    <parent link="l_link5"/>
    <child link="l_link6"/>
    <axis xyz="0 1 0"/>
    <limit effort="0" velocity="0" lower="-2.2299" upper="2.2299"/>
  </joint>

  <link name="l_link7">
    <visual>
      <geometry>
        <box size="0.1 0.1 0.1666"/>
      </geometry>
    </visual>
  </link>

  <joint name="l_joint7" type="revolute">
    <origin xyz="0 0.00030429 0.1666" rpy="0 0 0"/>
    <parent link="l_link6"/>
    <child link="l_link7"/>
    <axis xyz="0 0 1"/>
    <limit effort="0" velocity="0" lower="-6.2800" upper="6.2800"/>
  </joint>

  <!-- ... (Rest of left arm joints/links unchanged) ... -->
  <!-- Include all remaining left arm links/joints from original file -->
</robot>